[2023-09-26 06:10:37,823] {taskinstance.py:1159} INFO - Dependencies all met for <TaskInstance: 1_dags.get_province_daily manual__2023-09-26T02:58:18.564755+00:00 [queued]>
[2023-09-26 06:10:37,836] {taskinstance.py:1159} INFO - Dependencies all met for <TaskInstance: 1_dags.get_province_daily manual__2023-09-26T02:58:18.564755+00:00 [queued]>
[2023-09-26 06:10:37,836] {taskinstance.py:1356} INFO - 
--------------------------------------------------------------------------------
[2023-09-26 06:10:37,837] {taskinstance.py:1357} INFO - Starting attempt 24 of 24
[2023-09-26 06:10:37,837] {taskinstance.py:1358} INFO - 
--------------------------------------------------------------------------------
[2023-09-26 06:10:37,857] {taskinstance.py:1377} INFO - Executing <Task(PythonOperator): get_province_daily> on 2023-09-26 02:58:18.564755+00:00
[2023-09-26 06:10:37,865] {standard_task_runner.py:52} INFO - Started process 2647 to run task
[2023-09-26 06:10:37,873] {standard_task_runner.py:79} INFO - Running: ['***', 'tasks', 'run', '1_dags', 'get_province_daily', 'manual__2023-09-26T02:58:18.564755+00:00', '--job-id', '56', '--raw', '--subdir', 'DAGS_FOLDER/1_dags.py', '--cfg-path', '/tmp/tmpj55v5s6l', '--error-file', '/tmp/tmpr_a59egv']
[2023-09-26 06:10:37,874] {standard_task_runner.py:80} INFO - Job 56: Subtask get_province_daily
[2023-09-26 06:10:37,984] {task_command.py:369} INFO - Running <TaskInstance: 1_dags.get_province_daily manual__2023-09-26T02:58:18.564755+00:00 [running]> on host 615eeecb9afd
[2023-09-26 06:10:38,063] {taskinstance.py:1571} INFO - Exporting the following env vars:
AIRFLOW_CTX_DAG_OWNER=***
AIRFLOW_CTX_DAG_ID=1_dags
AIRFLOW_CTX_TASK_ID=get_province_daily
AIRFLOW_CTX_EXECUTION_DATE=2023-09-26T02:58:18.564755+00:00
AIRFLOW_CTX_TRY_NUMBER=24
AIRFLOW_CTX_DAG_RUN_ID=manual__2023-09-26T02:58:18.564755+00:00
[2023-09-26 06:10:38,460] {taskinstance.py:1889} ERROR - Task failed with exception
Traceback (most recent call last):
  File "/home/airflow/.local/lib/python3.7/site-packages/airflow/operators/python.py", line 171, in execute
    return_value = self.execute_callable()
  File "/home/airflow/.local/lib/python3.7/site-packages/airflow/operators/python.py", line 189, in execute_callable
    return self.python_callable(*self.op_args, **self.op_kwargs)
  File "/opt/airflow/dags/1_dags.py", line 88, in fun_insert_province_daily
    transformer.transform_daily_province()
  File "/opt/airflow/dags/modules/transformer.py", line 140, in transform_daily_province
    total_sql = row2['a'].__dict__
AttributeError: 'decimal.Decimal' object has no attribute '__dict__'
[2023-09-26 06:10:38,484] {taskinstance.py:1400} INFO - Marking task as FAILED. dag_id=1_dags, task_id=get_province_daily, execution_date=20230926T025818, start_date=20230926T061037, end_date=20230926T061038
[2023-09-26 06:10:38,498] {standard_task_runner.py:97} ERROR - Failed to execute job 56 for task get_province_daily ('decimal.Decimal' object has no attribute '__dict__'; 2647)
[2023-09-26 06:10:38,529] {local_task_job.py:156} INFO - Task exited with return code 1
[2023-09-26 06:10:38,559] {local_task_job.py:273} INFO - 0 downstream tasks scheduled from follow-on schedule check
