[2023-09-25 16:29:01,300] {taskinstance.py:1159} INFO - Dependencies all met for <TaskInstance: 1_dags.get_data_from_api scheduled__2023-09-24T00:00:00+00:00 [queued]>
[2023-09-25 16:29:01,313] {taskinstance.py:1159} INFO - Dependencies all met for <TaskInstance: 1_dags.get_data_from_api scheduled__2023-09-24T00:00:00+00:00 [queued]>
[2023-09-25 16:29:01,314] {taskinstance.py:1356} INFO - 
--------------------------------------------------------------------------------
[2023-09-25 16:29:01,314] {taskinstance.py:1357} INFO - Starting attempt 1 of 1
[2023-09-25 16:29:01,315] {taskinstance.py:1358} INFO - 
--------------------------------------------------------------------------------
[2023-09-25 16:29:01,336] {taskinstance.py:1377} INFO - Executing <Task(PythonOperator): get_data_from_api> on 2023-09-24 00:00:00+00:00
[2023-09-25 16:29:01,351] {standard_task_runner.py:52} INFO - Started process 246 to run task
[2023-09-25 16:29:01,406] {standard_task_runner.py:79} INFO - Running: ['***', 'tasks', 'run', '1_dags', 'get_data_from_api', 'scheduled__2023-09-24T00:00:00+00:00', '--job-id', '4', '--raw', '--subdir', 'DAGS_FOLDER/1_dags.py', '--cfg-path', '/tmp/tmpwzgwp4y8', '--error-file', '/tmp/tmpm03g9hdu']
[2023-09-25 16:29:01,411] {standard_task_runner.py:80} INFO - Job 4: Subtask get_data_from_api
[2023-09-25 16:29:01,768] {task_command.py:369} INFO - Running <TaskInstance: 1_dags.get_data_from_api scheduled__2023-09-24T00:00:00+00:00 [running]> on host 615eeecb9afd
[2023-09-25 16:29:02,025] {taskinstance.py:1571} INFO - Exporting the following env vars:
AIRFLOW_CTX_DAG_OWNER=***
AIRFLOW_CTX_DAG_ID=1_dags
AIRFLOW_CTX_TASK_ID=get_data_from_api
AIRFLOW_CTX_EXECUTION_DATE=2023-09-24T00:00:00+00:00
AIRFLOW_CTX_TRY_NUMBER=1
AIRFLOW_CTX_DAG_RUN_ID=scheduled__2023-09-24T00:00:00+00:00
[2023-09-25 16:29:02,026] {taskinstance.py:1889} ERROR - Task failed with exception
Traceback (most recent call last):
  File "/home/airflow/.local/lib/python3.7/site-packages/airflow/operators/python.py", line 171, in execute
    return_value = self.execute_callable()
  File "/home/airflow/.local/lib/python3.7/site-packages/airflow/operators/python.py", line 189, in execute_callable
    return self.python_callable(*self.op_args, **self.op_kwargs)
  File "/opt/airflow/dags/1_dags.py", line 14, in fun_get_data_from_api
    scraper = CovidScraper(Variable.get('url_covid_tracker'))
NameError: name 'CovidScraper' is not defined
[2023-09-25 16:29:02,043] {taskinstance.py:1400} INFO - Marking task as FAILED. dag_id=1_dags, task_id=get_data_from_api, execution_date=20230924T000000, start_date=20230925T162901, end_date=20230925T162902
[2023-09-25 16:29:02,060] {standard_task_runner.py:97} ERROR - Failed to execute job 4 for task get_data_from_api (name 'CovidScraper' is not defined; 246)
[2023-09-25 16:29:02,073] {local_task_job.py:156} INFO - Task exited with return code 1
[2023-09-25 16:29:02,106] {local_task_job.py:273} INFO - 0 downstream tasks scheduled from follow-on schedule check
