[2023-09-25 16:29:01,303] {taskinstance.py:1159} INFO - Dependencies all met for <TaskInstance: 1_dags.get_data_from_api manual__2023-09-25T16:28:57.423014+00:00 [queued]>
[2023-09-25 16:29:01,324] {taskinstance.py:1159} INFO - Dependencies all met for <TaskInstance: 1_dags.get_data_from_api manual__2023-09-25T16:28:57.423014+00:00 [queued]>
[2023-09-25 16:29:01,324] {taskinstance.py:1356} INFO - 
--------------------------------------------------------------------------------
[2023-09-25 16:29:01,325] {taskinstance.py:1357} INFO - Starting attempt 1 of 1
[2023-09-25 16:29:01,326] {taskinstance.py:1358} INFO - 
--------------------------------------------------------------------------------
[2023-09-25 16:29:01,370] {taskinstance.py:1377} INFO - Executing <Task(PythonOperator): get_data_from_api> on 2023-09-25 16:28:57.423014+00:00
[2023-09-25 16:29:01,402] {standard_task_runner.py:52} INFO - Started process 247 to run task
[2023-09-25 16:29:01,437] {standard_task_runner.py:79} INFO - Running: ['***', 'tasks', 'run', '1_dags', 'get_data_from_api', 'manual__2023-09-25T16:28:57.423014+00:00', '--job-id', '5', '--raw', '--subdir', 'DAGS_FOLDER/1_dags.py', '--cfg-path', '/tmp/tmpzfdzyeq9', '--error-file', '/tmp/tmpueyqdl19']
[2023-09-25 16:29:01,439] {standard_task_runner.py:80} INFO - Job 5: Subtask get_data_from_api
[2023-09-25 16:29:01,872] {task_command.py:369} INFO - Running <TaskInstance: 1_dags.get_data_from_api manual__2023-09-25T16:28:57.423014+00:00 [running]> on host 615eeecb9afd
[2023-09-25 16:29:02,060] {taskinstance.py:1571} INFO - Exporting the following env vars:
AIRFLOW_CTX_DAG_OWNER=***
AIRFLOW_CTX_DAG_ID=1_dags
AIRFLOW_CTX_TASK_ID=get_data_from_api
AIRFLOW_CTX_EXECUTION_DATE=2023-09-25T16:28:57.423014+00:00
AIRFLOW_CTX_TRY_NUMBER=1
AIRFLOW_CTX_DAG_RUN_ID=manual__2023-09-25T16:28:57.423014+00:00
[2023-09-25 16:29:02,065] {taskinstance.py:1889} ERROR - Task failed with exception
Traceback (most recent call last):
  File "/home/airflow/.local/lib/python3.7/site-packages/airflow/operators/python.py", line 171, in execute
    return_value = self.execute_callable()
  File "/home/airflow/.local/lib/python3.7/site-packages/airflow/operators/python.py", line 189, in execute_callable
    return self.python_callable(*self.op_args, **self.op_kwargs)
  File "/opt/airflow/dags/1_dags.py", line 14, in fun_get_data_from_api
    scraper = CovidScraper(Variable.get('url_covid_tracker'))
NameError: name 'CovidScraper' is not defined
[2023-09-25 16:29:02,081] {taskinstance.py:1400} INFO - Marking task as FAILED. dag_id=1_dags, task_id=get_data_from_api, execution_date=20230925T162857, start_date=20230925T162901, end_date=20230925T162902
[2023-09-25 16:29:02,092] {standard_task_runner.py:97} ERROR - Failed to execute job 5 for task get_data_from_api (name 'CovidScraper' is not defined; 247)
[2023-09-25 16:29:02,140] {local_task_job.py:156} INFO - Task exited with return code 1
[2023-09-25 16:29:02,273] {local_task_job.py:273} INFO - 0 downstream tasks scheduled from follow-on schedule check
