[2023-09-25 16:30:02,768] {taskinstance.py:1159} INFO - Dependencies all met for <TaskInstance: 1_dags.get_data_from_api manual__2023-09-25T16:28:57.423014+00:00 [queued]>
[2023-09-25 16:30:02,779] {taskinstance.py:1159} INFO - Dependencies all met for <TaskInstance: 1_dags.get_data_from_api manual__2023-09-25T16:28:57.423014+00:00 [queued]>
[2023-09-25 16:30:02,781] {taskinstance.py:1356} INFO - 
--------------------------------------------------------------------------------
[2023-09-25 16:30:02,782] {taskinstance.py:1357} INFO - Starting attempt 2 of 2
[2023-09-25 16:30:02,783] {taskinstance.py:1358} INFO - 
--------------------------------------------------------------------------------
[2023-09-25 16:30:02,815] {taskinstance.py:1377} INFO - Executing <Task(PythonOperator): get_data_from_api> on 2023-09-25 16:28:57.423014+00:00
[2023-09-25 16:30:02,823] {standard_task_runner.py:52} INFO - Started process 271 to run task
[2023-09-25 16:30:02,827] {standard_task_runner.py:79} INFO - Running: ['***', 'tasks', 'run', '1_dags', 'get_data_from_api', 'manual__2023-09-25T16:28:57.423014+00:00', '--job-id', '7', '--raw', '--subdir', 'DAGS_FOLDER/1_dags.py', '--cfg-path', '/tmp/tmp7mv5shl1', '--error-file', '/tmp/tmpphg87tnf']
[2023-09-25 16:30:02,828] {standard_task_runner.py:80} INFO - Job 7: Subtask get_data_from_api
[2023-09-25 16:30:02,892] {task_command.py:369} INFO - Running <TaskInstance: 1_dags.get_data_from_api manual__2023-09-25T16:28:57.423014+00:00 [running]> on host 615eeecb9afd
[2023-09-25 16:30:02,965] {taskinstance.py:1571} INFO - Exporting the following env vars:
AIRFLOW_CTX_DAG_OWNER=***
AIRFLOW_CTX_DAG_ID=1_dags
AIRFLOW_CTX_TASK_ID=get_data_from_api
AIRFLOW_CTX_EXECUTION_DATE=2023-09-25T16:28:57.423014+00:00
AIRFLOW_CTX_TRY_NUMBER=2
AIRFLOW_CTX_DAG_RUN_ID=manual__2023-09-25T16:28:57.423014+00:00
[2023-09-25 16:30:03,370] {covid_scrapper.py:12} INFO - GETT
[2023-09-25 16:30:03,374] {covid_scrapper.py:14} INFO - DATA READY
[2023-09-25 16:30:03,384] {logging_mixin.py:115} INFO - <class 'pandas.core.frame.DataFrame'>
RangeIndex: 145 entries, 0 to 144
Data columns (total 20 columns):
 #   Column                    Non-Null Count  Dtype 
---  ------                    --------------  ----- 
 0   CLOSECONTACT              145 non-null    int64 
 1   CONFIRMATION              145 non-null    int64 
 2   PROBABLE                  145 non-null    int64 
 3   SUSPECT                   145 non-null    int64 
 4   closecontact_dikarantina  145 non-null    int64 
 5   closecontact_discarded    145 non-null    int64 
 6   closecontact_meninggal    145 non-null    int64 
 7   confirmation_meninggal    145 non-null    int64 
 8   confirmation_sembuh       145 non-null    int64 
 9   kode_kab                  145 non-null    object
 10  kode_prov                 145 non-null    object
 11  nama_kab                  145 non-null    object
 12  nama_prov                 145 non-null    object
 13  probable_diisolasi        145 non-null    int64 
 14  probable_discarded        145 non-null    int64 
 15  probable_meninggal        145 non-null    int64 
 16  suspect_diisolasi         145 non-null    int64 
 17  suspect_discarded         145 non-null    int64 
 18  suspect_meninggal         145 non-null    int64 
 19  tanggal                   145 non-null    object
dtypes: int64(15), object(5)
memory usage: 22.8+ KB
[2023-09-25 16:30:03,384] {logging_mixin.py:115} INFO - None
[2023-09-25 16:30:03,418] {1_dags.py:35} ERROR - (mysql.connector.errors.DatabaseError) 1130 (HY000): Host '172.18.0.1' is not allowed to connect to this MySQL server
(Background on this error at: http://sqlalche.me/e/14/4xp6)
[2023-09-25 16:30:03,418] {taskinstance.py:1889} ERROR - Task failed with exception
Traceback (most recent call last):
  File "/home/airflow/.local/lib/python3.7/site-packages/airflow/operators/python.py", line 171, in execute
    return_value = self.execute_callable()
  File "/home/airflow/.local/lib/python3.7/site-packages/airflow/operators/python.py", line 189, in execute_callable
    return self.python_callable(*self.op_args, **self.op_kwargs)
  File "/opt/airflow/dags/1_dags.py", line 38, in fun_get_data_from_api
    data.to_sql(con-engine_sql, name="covid_jabar", index=False)
NameError: name 'con' is not defined
[2023-09-25 16:30:03,434] {taskinstance.py:1400} INFO - Marking task as FAILED. dag_id=1_dags, task_id=get_data_from_api, execution_date=20230925T162857, start_date=20230925T163002, end_date=20230925T163003
[2023-09-25 16:30:03,451] {standard_task_runner.py:97} ERROR - Failed to execute job 7 for task get_data_from_api (name 'con' is not defined; 271)
[2023-09-25 16:30:03,482] {local_task_job.py:156} INFO - Task exited with return code 1
[2023-09-25 16:30:03,541] {local_task_job.py:273} INFO - 0 downstream tasks scheduled from follow-on schedule check
