[2023-09-26 03:00:28,839] {taskinstance.py:1159} INFO - Dependencies all met for <TaskInstance: 1_dags.generate_dim_data manual__2023-09-26T02:58:18.564755+00:00 [queued]>
[2023-09-26 03:00:28,847] {taskinstance.py:1159} INFO - Dependencies all met for <TaskInstance: 1_dags.generate_dim_data manual__2023-09-26T02:58:18.564755+00:00 [queued]>
[2023-09-26 03:00:28,848] {taskinstance.py:1356} INFO - 
--------------------------------------------------------------------------------
[2023-09-26 03:00:28,848] {taskinstance.py:1357} INFO - Starting attempt 2 of 2
[2023-09-26 03:00:28,849] {taskinstance.py:1358} INFO - 
--------------------------------------------------------------------------------
[2023-09-26 03:00:28,862] {taskinstance.py:1377} INFO - Executing <Task(PythonOperator): generate_dim_data> on 2023-09-26 02:58:18.564755+00:00
[2023-09-26 03:00:28,867] {standard_task_runner.py:52} INFO - Started process 289 to run task
[2023-09-26 03:00:28,869] {standard_task_runner.py:79} INFO - Running: ['***', 'tasks', 'run', '1_dags', 'generate_dim_data', 'manual__2023-09-26T02:58:18.564755+00:00', '--job-id', '18', '--raw', '--subdir', 'DAGS_FOLDER/1_dags.py', '--cfg-path', '/tmp/tmpffng95kc', '--error-file', '/tmp/tmplcu4cry4']
[2023-09-26 03:00:28,870] {standard_task_runner.py:80} INFO - Job 18: Subtask generate_dim_data
[2023-09-26 03:00:28,999] {task_command.py:369} INFO - Running <TaskInstance: 1_dags.generate_dim_data manual__2023-09-26T02:58:18.564755+00:00 [running]> on host 615eeecb9afd
[2023-09-26 03:00:29,152] {taskinstance.py:1571} INFO - Exporting the following env vars:
AIRFLOW_CTX_DAG_OWNER=***
AIRFLOW_CTX_DAG_ID=1_dags
AIRFLOW_CTX_TASK_ID=generate_dim_data
AIRFLOW_CTX_EXECUTION_DATE=2023-09-26T02:58:18.564755+00:00
AIRFLOW_CTX_TRY_NUMBER=2
AIRFLOW_CTX_DAG_RUN_ID=manual__2023-09-26T02:58:18.564755+00:00
[2023-09-26 03:00:29,240] {taskinstance.py:1889} ERROR - Task failed with exception
Traceback (most recent call last):
  File "/home/airflow/.local/lib/python3.7/site-packages/airflow/operators/python.py", line 171, in execute
    return_value = self.execute_callable()
  File "/home/airflow/.local/lib/python3.7/site-packages/airflow/operators/python.py", line 189, in execute_callable
    return self.python_callable(*self.op_args, **self.op_kwargs)
  File "/opt/airflow/dags/1_dags.py", line 63, in fun_generate_dim
    transformer.transform_dim_case()
  File "/opt/airflow/dags/modules/transformer.py", line 60, in transform_dim_case
    Base.metadata.create_all(engine)
NameError: name 'engine' is not defined
[2023-09-26 03:00:29,260] {taskinstance.py:1400} INFO - Marking task as FAILED. dag_id=1_dags, task_id=generate_dim_data, execution_date=20230926T025818, start_date=20230926T030028, end_date=20230926T030029
[2023-09-26 03:00:29,270] {standard_task_runner.py:97} ERROR - Failed to execute job 18 for task generate_dim_data (name 'engine' is not defined; 289)
[2023-09-26 03:00:29,282] {local_task_job.py:156} INFO - Task exited with return code 1
[2023-09-26 03:00:29,311] {local_task_job.py:273} INFO - 0 downstream tasks scheduled from follow-on schedule check
