[2023-09-26 04:22:54,812] {taskinstance.py:1159} INFO - Dependencies all met for <TaskInstance: 1_dags.generate_dim_data manual__2023-09-26T02:58:18.564755+00:00 [queued]>
[2023-09-26 04:22:54,824] {taskinstance.py:1159} INFO - Dependencies all met for <TaskInstance: 1_dags.generate_dim_data manual__2023-09-26T02:58:18.564755+00:00 [queued]>
[2023-09-26 04:22:54,824] {taskinstance.py:1356} INFO - 
--------------------------------------------------------------------------------
[2023-09-26 04:22:54,824] {taskinstance.py:1357} INFO - Starting attempt 8 of 8
[2023-09-26 04:22:54,825] {taskinstance.py:1358} INFO - 
--------------------------------------------------------------------------------
[2023-09-26 04:22:54,843] {taskinstance.py:1377} INFO - Executing <Task(PythonOperator): generate_dim_data> on 2023-09-26 02:58:18.564755+00:00
[2023-09-26 04:22:54,850] {standard_task_runner.py:79} INFO - Running: ['***', 'tasks', 'run', '1_dags', 'generate_dim_data', 'manual__2023-09-26T02:58:18.564755+00:00', '--job-id', '25', '--raw', '--subdir', 'DAGS_FOLDER/1_dags.py', '--cfg-path', '/tmp/tmpt13nejre', '--error-file', '/tmp/tmp2ffgdduw']
[2023-09-26 04:22:54,850] {standard_task_runner.py:52} INFO - Started process 1288 to run task
[2023-09-26 04:22:54,851] {standard_task_runner.py:80} INFO - Job 25: Subtask generate_dim_data
[2023-09-26 04:22:54,904] {task_command.py:369} INFO - Running <TaskInstance: 1_dags.generate_dim_data manual__2023-09-26T02:58:18.564755+00:00 [running]> on host 615eeecb9afd
[2023-09-26 04:22:54,971] {taskinstance.py:1571} INFO - Exporting the following env vars:
AIRFLOW_CTX_DAG_OWNER=***
AIRFLOW_CTX_DAG_ID=1_dags
AIRFLOW_CTX_TASK_ID=generate_dim_data
AIRFLOW_CTX_EXECUTION_DATE=2023-09-26T02:58:18.564755+00:00
AIRFLOW_CTX_TRY_NUMBER=8
AIRFLOW_CTX_DAG_RUN_ID=manual__2023-09-26T02:58:18.564755+00:00
[2023-09-26 04:22:55,199] {taskinstance.py:1889} ERROR - Task failed with exception
Traceback (most recent call last):
  File "/home/airflow/.local/lib/python3.7/site-packages/sqlalchemy/engine/base.py", line 1686, in _execute_context
    cursor, statement, parameters, context
  File "/home/airflow/.local/lib/python3.7/site-packages/sqlalchemy/dialects/postgresql/psycopg2.py", line 909, in do_executemany
    **kwargs
  File "/home/airflow/.local/lib/python3.7/site-packages/psycopg2/extras.py", line 1270, in execute_values
    cur.execute(b''.join(parts))
psycopg2.errors.UniqueViolation: duplicate key value violates unique constraint "dim_case_pkey"
DETAIL:  Key (id)=(1) already exists.


The above exception was the direct cause of the following exception:

Traceback (most recent call last):
  File "/home/airflow/.local/lib/python3.7/site-packages/airflow/operators/python.py", line 171, in execute
    return_value = self.execute_callable()
  File "/home/airflow/.local/lib/python3.7/site-packages/airflow/operators/python.py", line 189, in execute_callable
    return self.python_callable(*self.op_args, **self.op_kwargs)
  File "/opt/airflow/dags/1_dags.py", line 63, in fun_generate_dim
    transformer.transform_dim_case()
  File "/opt/airflow/dags/modules/transformer.py", line 70, in transform_dim_case
    df.to_sql('dim_case',con=self.db_postgre,if_exists='append',index=False)
  File "/home/airflow/.local/lib/python3.7/site-packages/pandas/core/generic.py", line 2882, in to_sql
    method=method,
  File "/home/airflow/.local/lib/python3.7/site-packages/pandas/io/sql.py", line 728, in to_sql
    **engine_kwargs,
  File "/home/airflow/.local/lib/python3.7/site-packages/pandas/io/sql.py", line 1770, in to_sql
    **engine_kwargs,
  File "/home/airflow/.local/lib/python3.7/site-packages/pandas/io/sql.py", line 1350, in insert_records
    raise err
  File "/home/airflow/.local/lib/python3.7/site-packages/pandas/io/sql.py", line 1340, in insert_records
    table.insert(chunksize=chunksize, method=method)
  File "/home/airflow/.local/lib/python3.7/site-packages/pandas/io/sql.py", line 967, in insert
    exec_insert(conn, keys, chunk_iter)
  File "/home/airflow/.local/lib/python3.7/site-packages/pandas/io/sql.py", line 882, in _execute_insert
    conn.execute(self.table.insert(), data)
  File "/home/airflow/.local/lib/python3.7/site-packages/sqlalchemy/engine/base.py", line 1200, in execute
    return meth(self, multiparams, params, _EMPTY_EXECUTION_OPTS)
  File "/home/airflow/.local/lib/python3.7/site-packages/sqlalchemy/sql/elements.py", line 314, in _execute_on_connection
    self, multiparams, params, execution_options
  File "/home/airflow/.local/lib/python3.7/site-packages/sqlalchemy/engine/base.py", line 1399, in _execute_clauseelement
    cache_hit=cache_hit,
  File "/home/airflow/.local/lib/python3.7/site-packages/sqlalchemy/engine/base.py", line 1749, in _execute_context
    e, statement, parameters, cursor, context
  File "/home/airflow/.local/lib/python3.7/site-packages/sqlalchemy/engine/base.py", line 1930, in _handle_dbapi_exception
    sqlalchemy_exception, with_traceback=exc_info[2], from_=e
  File "/home/airflow/.local/lib/python3.7/site-packages/sqlalchemy/util/compat.py", line 211, in raise_
    raise exception
  File "/home/airflow/.local/lib/python3.7/site-packages/sqlalchemy/engine/base.py", line 1686, in _execute_context
    cursor, statement, parameters, context
  File "/home/airflow/.local/lib/python3.7/site-packages/sqlalchemy/dialects/postgresql/psycopg2.py", line 909, in do_executemany
    **kwargs
  File "/home/airflow/.local/lib/python3.7/site-packages/psycopg2/extras.py", line 1270, in execute_values
    cur.execute(b''.join(parts))
sqlalchemy.exc.IntegrityError: (psycopg2.errors.UniqueViolation) duplicate key value violates unique constraint "dim_case_pkey"
DETAIL:  Key (id)=(1) already exists.

[SQL: INSERT INTO dim_case (id, status_name, status_detail, status) VALUES (%(id)s, %(status_name)s, %(status_detail)s, %(status)s)]
[parameters: ({'id': 1, 'status_name': 'close_contact', 'status_detail': 'dikarantina', 'status': 'closecontact_dikarantina'}, {'id': 2, 'status_name': 'close_contact', 'status_detail': 'discarded', 'status': 'closecontact_discarded'}, {'id': 3, 'status_name': 'close_contact', 'status_detail': 'meninggal', 'status': 'closecontact_meninggal'}, {'id': 4, 'status_name': 'confirmation', 'status_detail': 'meninggal', 'status': 'confirmation_meninggal'}, {'id': 5, 'status_name': 'confirmation', 'status_detail': 'sembuh', 'status': 'confirmation_sembuh'}, {'id': 6, 'status_name': 'probable', 'status_detail': 'diisolasi', 'status': 'probable_diisolasi'}, {'id': 7, 'status_name': 'probable', 'status_detail': 'discarded', 'status': 'probable_discarded'}, {'id': 8, 'status_name': 'probable', 'status_detail': 'meninggal', 'status': 'probable_meninggal'}  ... displaying 10 of 11 total bound parameter sets ...  {'id': 10, 'status_name': 'suspect', 'status_detail': 'discarded', 'status': 'suspect_discarded'}, {'id': 11, 'status_name': 'suspect', 'status_detail': 'meninggal', 'status': 'suspect_meninggal'})]
(Background on this error at: http://sqlalche.me/e/14/gkpj)
[2023-09-26 04:22:55,247] {taskinstance.py:1400} INFO - Marking task as FAILED. dag_id=1_dags, task_id=generate_dim_data, execution_date=20230926T025818, start_date=20230926T042254, end_date=20230926T042255
[2023-09-26 04:22:55,273] {standard_task_runner.py:97} ERROR - Failed to execute job 25 for task generate_dim_data ((psycopg2.errors.UniqueViolation) duplicate key value violates unique constraint "dim_case_pkey"
DETAIL:  Key (id)=(1) already exists.

[SQL: INSERT INTO dim_case (id, status_name, status_detail, status) VALUES (%(id)s, %(status_name)s, %(status_detail)s, %(status)s)]
[parameters: ({'id': 1, 'status_name': 'close_contact', 'status_detail': 'dikarantina', 'status': 'closecontact_dikarantina'}, {'id': 2, 'status_name': 'close_contact', 'status_detail': 'discarded', 'status': 'closecontact_discarded'}, {'id': 3, 'status_name': 'close_contact', 'status_detail': 'meninggal', 'status': 'closecontact_meninggal'}, {'id': 4, 'status_name': 'confirmation', 'status_detail': 'meninggal', 'status': 'confirmation_meninggal'}, {'id': 5, 'status_name': 'confirmation', 'status_detail': 'sembuh', 'status': 'confirmation_sembuh'}, {'id': 6, 'status_name': 'probable', 'status_detail': 'diisolasi', 'status': 'probable_diisolasi'}, {'id': 7, 'status_name': 'probable', 'status_detail': 'discarded', 'status': 'probable_discarded'}, {'id': 8, 'status_name': 'probable', 'status_detail': 'meninggal', 'status': 'probable_meninggal'}  ... displaying 10 of 11 total bound parameter sets ...  {'id': 10, 'status_name': 'suspect', 'status_detail': 'discarded', 'status': 'suspect_discarded'}, {'id': 11, 'status_name': 'suspect', 'status_detail': 'meninggal', 'status': 'suspect_meninggal'})]
(Background on this error at: http://sqlalche.me/e/14/gkpj); 1288)
[2023-09-26 04:22:55,307] {local_task_job.py:156} INFO - Task exited with return code 1
[2023-09-26 04:22:55,394] {local_task_job.py:273} INFO - 0 downstream tasks scheduled from follow-on schedule check
