[2023-09-26 03:10:18,858] {taskinstance.py:1159} INFO - Dependencies all met for <TaskInstance: 1_dags.generate_dim_data manual__2023-09-26T02:58:18.564755+00:00 [queued]>
[2023-09-26 03:10:18,874] {taskinstance.py:1159} INFO - Dependencies all met for <TaskInstance: 1_dags.generate_dim_data manual__2023-09-26T02:58:18.564755+00:00 [queued]>
[2023-09-26 03:10:18,874] {taskinstance.py:1356} INFO - 
--------------------------------------------------------------------------------
[2023-09-26 03:10:18,875] {taskinstance.py:1357} INFO - Starting attempt 6 of 6
[2023-09-26 03:10:18,876] {taskinstance.py:1358} INFO - 
--------------------------------------------------------------------------------
[2023-09-26 03:10:18,899] {taskinstance.py:1377} INFO - Executing <Task(PythonOperator): generate_dim_data> on 2023-09-26 02:58:18.564755+00:00
[2023-09-26 03:10:18,906] {standard_task_runner.py:52} INFO - Started process 421 to run task
[2023-09-26 03:10:18,910] {standard_task_runner.py:79} INFO - Running: ['***', 'tasks', 'run', '1_dags', 'generate_dim_data', 'manual__2023-09-26T02:58:18.564755+00:00', '--job-id', '22', '--raw', '--subdir', 'DAGS_FOLDER/1_dags.py', '--cfg-path', '/tmp/tmpd5bi65tl', '--error-file', '/tmp/tmpi599hlk9']
[2023-09-26 03:10:18,911] {standard_task_runner.py:80} INFO - Job 22: Subtask generate_dim_data
[2023-09-26 03:10:18,998] {task_command.py:369} INFO - Running <TaskInstance: 1_dags.generate_dim_data manual__2023-09-26T02:58:18.564755+00:00 [running]> on host 615eeecb9afd
[2023-09-26 03:10:19,078] {taskinstance.py:1571} INFO - Exporting the following env vars:
AIRFLOW_CTX_DAG_OWNER=***
AIRFLOW_CTX_DAG_ID=1_dags
AIRFLOW_CTX_TASK_ID=generate_dim_data
AIRFLOW_CTX_EXECUTION_DATE=2023-09-26T02:58:18.564755+00:00
AIRFLOW_CTX_TRY_NUMBER=6
AIRFLOW_CTX_DAG_RUN_ID=manual__2023-09-26T02:58:18.564755+00:00
[2023-09-26 03:10:19,161] {taskinstance.py:1889} ERROR - Task failed with exception
Traceback (most recent call last):
  File "/home/airflow/.local/lib/python3.7/site-packages/airflow/operators/python.py", line 171, in execute
    return_value = self.execute_callable()
  File "/home/airflow/.local/lib/python3.7/site-packages/airflow/operators/python.py", line 189, in execute_callable
    return self.python_callable(*self.op_args, **self.op_kwargs)
  File "/opt/airflow/dags/1_dags.py", line 63, in fun_generate_dim
    transformer.transform_dim_case()
  File "/opt/airflow/dags/modules/transformer.py", line 67, in transform_dim_case
    'status':['closecontact_dikarantina','closecontact_discarded','closecontact_meninggal','confirmation_meninggal','confirmation_sembuh','probable_diisolasi','probable_discarded','probable_meninggal','suspect_diisolasi','suspect_discarded']})
  File "/home/airflow/.local/lib/python3.7/site-packages/pandas/core/frame.py", line 614, in __init__
    mgr = dict_to_mgr(data, index, columns, dtype=dtype, copy=copy, typ=manager)
  File "/home/airflow/.local/lib/python3.7/site-packages/pandas/core/internals/construction.py", line 465, in dict_to_mgr
    arrays, data_names, index, columns, dtype=dtype, typ=typ, consolidate=copy
  File "/home/airflow/.local/lib/python3.7/site-packages/pandas/core/internals/construction.py", line 119, in arrays_to_mgr
    index = _extract_index(arrays)
  File "/home/airflow/.local/lib/python3.7/site-packages/pandas/core/internals/construction.py", line 635, in _extract_index
    raise ValueError("All arrays must be of the same length")
ValueError: All arrays must be of the same length
[2023-09-26 03:10:19,180] {taskinstance.py:1400} INFO - Marking task as FAILED. dag_id=1_dags, task_id=generate_dim_data, execution_date=20230926T025818, start_date=20230926T031018, end_date=20230926T031019
[2023-09-26 03:10:19,190] {standard_task_runner.py:97} ERROR - Failed to execute job 22 for task generate_dim_data (All arrays must be of the same length; 421)
[2023-09-26 03:10:19,203] {local_task_job.py:156} INFO - Task exited with return code 1
[2023-09-26 03:10:19,231] {local_task_job.py:273} INFO - 0 downstream tasks scheduled from follow-on schedule check
