[2023-09-26 03:09:44,059] {taskinstance.py:1159} INFO - Dependencies all met for <TaskInstance: 1_dags.generate_dim_data manual__2023-09-26T02:58:18.564755+00:00 [queued]>
[2023-09-26 03:09:44,077] {taskinstance.py:1159} INFO - Dependencies all met for <TaskInstance: 1_dags.generate_dim_data manual__2023-09-26T02:58:18.564755+00:00 [queued]>
[2023-09-26 03:09:44,078] {taskinstance.py:1356} INFO - 
--------------------------------------------------------------------------------
[2023-09-26 03:09:44,078] {taskinstance.py:1357} INFO - Starting attempt 5 of 5
[2023-09-26 03:09:44,079] {taskinstance.py:1358} INFO - 
--------------------------------------------------------------------------------
[2023-09-26 03:09:44,095] {taskinstance.py:1377} INFO - Executing <Task(PythonOperator): generate_dim_data> on 2023-09-26 02:58:18.564755+00:00
[2023-09-26 03:09:44,104] {standard_task_runner.py:52} INFO - Started process 409 to run task
[2023-09-26 03:09:44,113] {standard_task_runner.py:79} INFO - Running: ['***', 'tasks', 'run', '1_dags', 'generate_dim_data', 'manual__2023-09-26T02:58:18.564755+00:00', '--job-id', '21', '--raw', '--subdir', 'DAGS_FOLDER/1_dags.py', '--cfg-path', '/tmp/tmp32wk58vy', '--error-file', '/tmp/tmp35mu178x']
[2023-09-26 03:09:44,116] {standard_task_runner.py:80} INFO - Job 21: Subtask generate_dim_data
[2023-09-26 03:09:44,367] {task_command.py:369} INFO - Running <TaskInstance: 1_dags.generate_dim_data manual__2023-09-26T02:58:18.564755+00:00 [running]> on host 615eeecb9afd
[2023-09-26 03:09:44,547] {taskinstance.py:1571} INFO - Exporting the following env vars:
AIRFLOW_CTX_DAG_OWNER=***
AIRFLOW_CTX_DAG_ID=1_dags
AIRFLOW_CTX_TASK_ID=generate_dim_data
AIRFLOW_CTX_EXECUTION_DATE=2023-09-26T02:58:18.564755+00:00
AIRFLOW_CTX_TRY_NUMBER=5
AIRFLOW_CTX_DAG_RUN_ID=manual__2023-09-26T02:58:18.564755+00:00
[2023-09-26 03:09:44,766] {taskinstance.py:1889} ERROR - Task failed with exception
Traceback (most recent call last):
  File "/home/airflow/.local/lib/python3.7/site-packages/airflow/operators/python.py", line 171, in execute
    return_value = self.execute_callable()
  File "/home/airflow/.local/lib/python3.7/site-packages/airflow/operators/python.py", line 189, in execute_callable
    return self.python_callable(*self.op_args, **self.op_kwargs)
  File "/opt/airflow/dags/1_dags.py", line 63, in fun_generate_dim
    transformer.transform_dim_case()
  File "/opt/airflow/dags/modules/transformer.py", line 67, in transform_dim_case
    'status':['closecontact_dikarantina','closecontact_discarded','closecontact_meninggal','confirmation_meninggal','confirmation_sembuh','probable_diisolasi','probable_discarded','probable_meninggal','suspect_diisolasi','suspect_discarded']})
  File "/home/airflow/.local/lib/python3.7/site-packages/pandas/core/frame.py", line 614, in __init__
    mgr = dict_to_mgr(data, index, columns, dtype=dtype, copy=copy, typ=manager)
  File "/home/airflow/.local/lib/python3.7/site-packages/pandas/core/internals/construction.py", line 465, in dict_to_mgr
    arrays, data_names, index, columns, dtype=dtype, typ=typ, consolidate=copy
  File "/home/airflow/.local/lib/python3.7/site-packages/pandas/core/internals/construction.py", line 119, in arrays_to_mgr
    index = _extract_index(arrays)
  File "/home/airflow/.local/lib/python3.7/site-packages/pandas/core/internals/construction.py", line 635, in _extract_index
    raise ValueError("All arrays must be of the same length")
ValueError: All arrays must be of the same length
[2023-09-26 03:09:44,895] {taskinstance.py:1400} INFO - Marking task as FAILED. dag_id=1_dags, task_id=generate_dim_data, execution_date=20230926T025818, start_date=20230926T030944, end_date=20230926T030944
[2023-09-26 03:09:44,922] {standard_task_runner.py:97} ERROR - Failed to execute job 21 for task generate_dim_data (All arrays must be of the same length; 409)
[2023-09-26 03:09:44,963] {local_task_job.py:156} INFO - Task exited with return code 1
[2023-09-26 03:09:45,042] {local_task_job.py:273} INFO - 0 downstream tasks scheduled from follow-on schedule check
