[2023-09-26 02:58:24,891] {taskinstance.py:1159} INFO - Dependencies all met for <TaskInstance: 1_dags.generate_dim_data manual__2023-09-26T02:58:18.564755+00:00 [queued]>
[2023-09-26 02:58:24,900] {taskinstance.py:1159} INFO - Dependencies all met for <TaskInstance: 1_dags.generate_dim_data manual__2023-09-26T02:58:18.564755+00:00 [queued]>
[2023-09-26 02:58:24,901] {taskinstance.py:1356} INFO - 
--------------------------------------------------------------------------------
[2023-09-26 02:58:24,901] {taskinstance.py:1357} INFO - Starting attempt 1 of 1
[2023-09-26 02:58:24,902] {taskinstance.py:1358} INFO - 
--------------------------------------------------------------------------------
[2023-09-26 02:58:24,915] {taskinstance.py:1377} INFO - Executing <Task(PythonOperator): generate_dim_data> on 2023-09-26 02:58:18.564755+00:00
[2023-09-26 02:58:24,922] {standard_task_runner.py:52} INFO - Started process 262 to run task
[2023-09-26 02:58:24,926] {standard_task_runner.py:79} INFO - Running: ['***', 'tasks', 'run', '1_dags', 'generate_dim_data', 'manual__2023-09-26T02:58:18.564755+00:00', '--job-id', '17', '--raw', '--subdir', 'DAGS_FOLDER/1_dags.py', '--cfg-path', '/tmp/tmp2dj26ai8', '--error-file', '/tmp/tmpqgu0qt67']
[2023-09-26 02:58:24,927] {standard_task_runner.py:80} INFO - Job 17: Subtask generate_dim_data
[2023-09-26 02:58:24,980] {task_command.py:369} INFO - Running <TaskInstance: 1_dags.generate_dim_data manual__2023-09-26T02:58:18.564755+00:00 [running]> on host 615eeecb9afd
[2023-09-26 02:58:25,087] {taskinstance.py:1571} INFO - Exporting the following env vars:
AIRFLOW_CTX_DAG_OWNER=***
AIRFLOW_CTX_DAG_ID=1_dags
AIRFLOW_CTX_TASK_ID=generate_dim_data
AIRFLOW_CTX_EXECUTION_DATE=2023-09-26T02:58:18.564755+00:00
AIRFLOW_CTX_TRY_NUMBER=1
AIRFLOW_CTX_DAG_RUN_ID=manual__2023-09-26T02:58:18.564755+00:00
[2023-09-26 02:58:25,123] {taskinstance.py:1889} ERROR - Task failed with exception
Traceback (most recent call last):
  File "/home/airflow/.local/lib/python3.7/site-packages/airflow/operators/python.py", line 171, in execute
    return_value = self.execute_callable()
  File "/home/airflow/.local/lib/python3.7/site-packages/airflow/operators/python.py", line 189, in execute_callable
    return self.python_callable(*self.op_args, **self.op_kwargs)
  File "/opt/airflow/dags/1_dags.py", line 63, in fun_generate_dim
    transformer.transform_dim_case()
  File "/opt/airflow/dags/modules/transformer.py", line 57, in transform_dim_case
    Session = sessionmaker(bind=db_postgre)
NameError: name 'db_postgre' is not defined
[2023-09-26 02:58:25,145] {taskinstance.py:1400} INFO - Marking task as FAILED. dag_id=1_dags, task_id=generate_dim_data, execution_date=20230926T025818, start_date=20230926T025824, end_date=20230926T025825
[2023-09-26 02:58:25,155] {standard_task_runner.py:97} ERROR - Failed to execute job 17 for task generate_dim_data (name 'db_postgre' is not defined; 262)
[2023-09-26 02:58:25,179] {local_task_job.py:156} INFO - Task exited with return code 1
[2023-09-26 02:58:25,214] {local_task_job.py:273} INFO - 0 downstream tasks scheduled from follow-on schedule check
