[2023-09-26 03:02:51,257] {taskinstance.py:1159} INFO - Dependencies all met for <TaskInstance: 1_dags.generate_dim_data manual__2023-09-26T02:58:18.564755+00:00 [queued]>
[2023-09-26 03:02:51,265] {taskinstance.py:1159} INFO - Dependencies all met for <TaskInstance: 1_dags.generate_dim_data manual__2023-09-26T02:58:18.564755+00:00 [queued]>
[2023-09-26 03:02:51,266] {taskinstance.py:1356} INFO - 
--------------------------------------------------------------------------------
[2023-09-26 03:02:51,266] {taskinstance.py:1357} INFO - Starting attempt 3 of 3
[2023-09-26 03:02:51,267] {taskinstance.py:1358} INFO - 
--------------------------------------------------------------------------------
[2023-09-26 03:02:51,280] {taskinstance.py:1377} INFO - Executing <Task(PythonOperator): generate_dim_data> on 2023-09-26 02:58:18.564755+00:00
[2023-09-26 03:02:51,294] {standard_task_runner.py:52} INFO - Started process 322 to run task
[2023-09-26 03:02:51,296] {standard_task_runner.py:79} INFO - Running: ['***', 'tasks', 'run', '1_dags', 'generate_dim_data', 'manual__2023-09-26T02:58:18.564755+00:00', '--job-id', '19', '--raw', '--subdir', 'DAGS_FOLDER/1_dags.py', '--cfg-path', '/tmp/tmpq2370x52', '--error-file', '/tmp/tmpk0s405t4']
[2023-09-26 03:02:51,297] {standard_task_runner.py:80} INFO - Job 19: Subtask generate_dim_data
[2023-09-26 03:02:51,526] {task_command.py:369} INFO - Running <TaskInstance: 1_dags.generate_dim_data manual__2023-09-26T02:58:18.564755+00:00 [running]> on host 615eeecb9afd
[2023-09-26 03:02:51,593] {taskinstance.py:1571} INFO - Exporting the following env vars:
AIRFLOW_CTX_DAG_OWNER=***
AIRFLOW_CTX_DAG_ID=1_dags
AIRFLOW_CTX_TASK_ID=generate_dim_data
AIRFLOW_CTX_EXECUTION_DATE=2023-09-26T02:58:18.564755+00:00
AIRFLOW_CTX_TRY_NUMBER=3
AIRFLOW_CTX_DAG_RUN_ID=manual__2023-09-26T02:58:18.564755+00:00
[2023-09-26 03:02:52,042] {taskinstance.py:1889} ERROR - Task failed with exception
Traceback (most recent call last):
  File "/home/airflow/.local/lib/python3.7/site-packages/airflow/operators/python.py", line 171, in execute
    return_value = self.execute_callable()
  File "/home/airflow/.local/lib/python3.7/site-packages/airflow/operators/python.py", line 189, in execute_callable
    return self.python_callable(*self.op_args, **self.op_kwargs)
  File "/opt/airflow/dags/1_dags.py", line 63, in fun_generate_dim
    transformer.transform_dim_case()
  File "/opt/airflow/dags/modules/transformer.py", line 63, in transform_dim_case
    df = pd.DataFrame({"id":[1,2,3,4,5,6,7,8,9,10,11],
NameError: name 'pd' is not defined
[2023-09-26 03:02:52,064] {taskinstance.py:1400} INFO - Marking task as FAILED. dag_id=1_dags, task_id=generate_dim_data, execution_date=20230926T025818, start_date=20230926T030251, end_date=20230926T030252
[2023-09-26 03:02:52,081] {standard_task_runner.py:97} ERROR - Failed to execute job 19 for task generate_dim_data (name 'pd' is not defined; 322)
[2023-09-26 03:02:52,113] {local_task_job.py:156} INFO - Task exited with return code 1
[2023-09-26 03:02:52,147] {local_task_job.py:273} INFO - 0 downstream tasks scheduled from follow-on schedule check
