[2023-09-26 04:24:22,168] {taskinstance.py:1159} INFO - Dependencies all met for <TaskInstance: 1_dags.get_district_daily manual__2023-09-26T02:58:18.564755+00:00 [queued]>
[2023-09-26 04:24:22,181] {taskinstance.py:1159} INFO - Dependencies all met for <TaskInstance: 1_dags.get_district_daily manual__2023-09-26T02:58:18.564755+00:00 [queued]>
[2023-09-26 04:24:22,181] {taskinstance.py:1356} INFO - 
--------------------------------------------------------------------------------
[2023-09-26 04:24:22,182] {taskinstance.py:1357} INFO - Starting attempt 1 of 1
[2023-09-26 04:24:22,182] {taskinstance.py:1358} INFO - 
--------------------------------------------------------------------------------
[2023-09-26 04:24:22,198] {taskinstance.py:1377} INFO - Executing <Task(PythonOperator): get_district_daily> on 2023-09-26 02:58:18.564755+00:00
[2023-09-26 04:24:22,209] {standard_task_runner.py:52} INFO - Started process 1315 to run task
[2023-09-26 04:24:22,222] {standard_task_runner.py:79} INFO - Running: ['***', 'tasks', 'run', '1_dags', 'get_district_daily', 'manual__2023-09-26T02:58:18.564755+00:00', '--job-id', '28', '--raw', '--subdir', 'DAGS_FOLDER/1_dags.py', '--cfg-path', '/tmp/tmpbf1uc8lj', '--error-file', '/tmp/tmpw2kyza06']
[2023-09-26 04:24:22,223] {standard_task_runner.py:80} INFO - Job 28: Subtask get_district_daily
[2023-09-26 04:24:22,461] {task_command.py:369} INFO - Running <TaskInstance: 1_dags.get_district_daily manual__2023-09-26T02:58:18.564755+00:00 [running]> on host 615eeecb9afd
[2023-09-26 04:24:22,602] {taskinstance.py:1571} INFO - Exporting the following env vars:
AIRFLOW_CTX_DAG_OWNER=***
AIRFLOW_CTX_DAG_ID=1_dags
AIRFLOW_CTX_TASK_ID=get_district_daily
AIRFLOW_CTX_EXECUTION_DATE=2023-09-26T02:58:18.564755+00:00
AIRFLOW_CTX_TRY_NUMBER=1
AIRFLOW_CTX_DAG_RUN_ID=manual__2023-09-26T02:58:18.564755+00:00
[2023-09-26 04:24:22,692] {taskinstance.py:1889} ERROR - Task failed with exception
Traceback (most recent call last):
  File "/home/airflow/.local/lib/python3.7/site-packages/airflow/operators/python.py", line 171, in execute
    return_value = self.execute_callable()
  File "/home/airflow/.local/lib/python3.7/site-packages/airflow/operators/python.py", line 189, in execute_callable
    return self.python_callable(*self.op_args, **self.op_kwargs)
  File "/opt/airflow/dags/1_dags.py", line 92, in fun_insert_district_daily
    get_conn_postgres = Connection.get_connection_from_secrets("Postgre")
  File "/home/airflow/.local/lib/python3.7/site-packages/airflow/models/connection.py", line 430, in get_connection_from_secrets
    raise AirflowNotFoundException(f"The conn_id `{conn_id}` isn't defined")
airflow.exceptions.AirflowNotFoundException: The conn_id `Postgre` isn't defined
[2023-09-26 04:24:22,706] {taskinstance.py:1400} INFO - Marking task as FAILED. dag_id=1_dags, task_id=get_district_daily, execution_date=20230926T025818, start_date=20230926T042422, end_date=20230926T042422
[2023-09-26 04:24:22,721] {standard_task_runner.py:97} ERROR - Failed to execute job 28 for task get_district_daily (The conn_id `Postgre` isn't defined; 1315)
[2023-09-26 04:24:22,761] {local_task_job.py:156} INFO - Task exited with return code 1
[2023-09-26 04:24:22,798] {local_task_job.py:273} INFO - 0 downstream tasks scheduled from follow-on schedule check
