[2023-09-26 04:36:38,369] {taskinstance.py:1159} INFO - Dependencies all met for <TaskInstance: 1_dags.get_district_daily manual__2023-09-26T02:58:18.564755+00:00 [queued]>
[2023-09-26 04:36:38,381] {taskinstance.py:1159} INFO - Dependencies all met for <TaskInstance: 1_dags.get_district_daily manual__2023-09-26T02:58:18.564755+00:00 [queued]>
[2023-09-26 04:36:38,382] {taskinstance.py:1356} INFO - 
--------------------------------------------------------------------------------
[2023-09-26 04:36:38,383] {taskinstance.py:1357} INFO - Starting attempt 3 of 3
[2023-09-26 04:36:38,383] {taskinstance.py:1358} INFO - 
--------------------------------------------------------------------------------
[2023-09-26 04:36:38,829] {taskinstance.py:1377} INFO - Executing <Task(PythonOperator): get_district_daily> on 2023-09-26 02:58:18.564755+00:00
[2023-09-26 04:36:38,857] {standard_task_runner.py:52} INFO - Started process 1469 to run task
[2023-09-26 04:36:38,888] {standard_task_runner.py:79} INFO - Running: ['***', 'tasks', 'run', '1_dags', 'get_district_daily', 'manual__2023-09-26T02:58:18.564755+00:00', '--job-id', '30', '--raw', '--subdir', 'DAGS_FOLDER/1_dags.py', '--cfg-path', '/tmp/tmpxq833qvr', '--error-file', '/tmp/tmp9693hvl4']
[2023-09-26 04:36:38,890] {standard_task_runner.py:80} INFO - Job 30: Subtask get_district_daily
[2023-09-26 04:36:39,492] {task_command.py:369} INFO - Running <TaskInstance: 1_dags.get_district_daily manual__2023-09-26T02:58:18.564755+00:00 [running]> on host 615eeecb9afd
[2023-09-26 04:36:40,062] {taskinstance.py:1571} INFO - Exporting the following env vars:
AIRFLOW_CTX_DAG_OWNER=***
AIRFLOW_CTX_DAG_ID=1_dags
AIRFLOW_CTX_TASK_ID=get_district_daily
AIRFLOW_CTX_EXECUTION_DATE=2023-09-26T02:58:18.564755+00:00
AIRFLOW_CTX_TRY_NUMBER=3
AIRFLOW_CTX_DAG_RUN_ID=manual__2023-09-26T02:58:18.564755+00:00
[2023-09-26 04:36:41,238] {taskinstance.py:1889} ERROR - Task failed with exception
Traceback (most recent call last):
  File "/home/airflow/.local/lib/python3.7/site-packages/airflow/operators/python.py", line 171, in execute
    return_value = self.execute_callable()
  File "/home/airflow/.local/lib/python3.7/site-packages/airflow/operators/python.py", line 189, in execute_callable
    return self.python_callable(*self.op_args, **self.op_kwargs)
  File "/opt/airflow/dags/1_dags.py", line 111, in fun_insert_district_daily
    transformer.transform_daily_district()
  File "/opt/airflow/dags/modules/transformer.py", line 115, in transform_daily_district
    new_case = District_Daily_Daily(district_id=row['kode_kab'],case_id=list_cas_id[case.index], date=row['tanggal'], total=row[case])
NameError: name 'District_Daily_Daily' is not defined
[2023-09-26 04:36:41,277] {taskinstance.py:1400} INFO - Marking task as FAILED. dag_id=1_dags, task_id=get_district_daily, execution_date=20230926T025818, start_date=20230926T043638, end_date=20230926T043641
[2023-09-26 04:36:41,298] {standard_task_runner.py:97} ERROR - Failed to execute job 30 for task get_district_daily (name 'District_Daily_Daily' is not defined; 1469)
[2023-09-26 04:36:41,343] {local_task_job.py:156} INFO - Task exited with return code 1
[2023-09-26 04:36:41,396] {local_task_job.py:273} INFO - 0 downstream tasks scheduled from follow-on schedule check
